Workbook

Sheet schedule
A1: matchlink | B1: description | C1: date | D1: time | E1: Home_Team | F1: Away_Team | G1: Round
A2: 57dotnff3xaafnxfltzt4czdg | C2: 46222 | D2: 19:00:00Z | G2: 3rd Place / Final
A3: 1wrjcpwj8cv0mb6d4yp67dams | C3: 46221 | D3: 21:00:00Z | G3: 3rd Place / Final
A4: 9jubv7maziug1x60neaq76g44 | C4: 46218 | D4: 19:00:00Z | G4: Semi Final
A5: 61zv9h8fu4v0812uihvl7m3h0 | C5: 46217 | D5: 19:00:00Z | G5: Semi Final
A6: 68n1p6yn5507yxvrrgfzod3bo | C6: 46215 | D6: 01:00:00Z | G6: Quarter Final
A7: 4mcheqqscjz2gduxagmcgeyhg | C7: 46214 | D7: 21:00:00Z | G7: Quarter Final
A8: 3a1xofm1wnspw1952k7e4du6s | C8: 46213 | D8: 19:00:00Z | G8: Quarter Final
A9: 1ot14rn6x26nlaxaxt27wkrv8 | C9: 46212 | D9: 20:00:00Z | G9: Quarter Final
A10: em70mwgw22fdt9i4womogw93o | B10: Switzerland v --- | C10: 46210 | D10: 20:00:00Z | E10: Switzerland | G10: Last 16
A11: ceq6z0bte8pgdbc2uwxni0x78 | C11: 46210 | D11: 16:00:00Z | G11: Last 16
A12: 7djxwsgj6k02ts4b8lj2akqok | B12: USA v Belgium | C12: 46210 | D12: 00:00:00Z | E12: USA | F12: Belgium | G12: Last 16
A13: 5fim3od605k9wne6uuiw641ec | B13: Portugal v Spain | C13: 46209 | D13: 19:00:00Z | E13: Portugal | F13: Spain | G13: Last 16
A14: b083yrj18tbck1z0og2evbhuc | B14: Mexico v England | C14: 46209 | D14: 00:00:00Z | E14: Mexico | F14: England | G14: Last 16
A15: 9fqb3vpytcmgk9pozahr7iz9w | B15: Brazil v Norway | C15: 46208 | D15: 20:00:00Z | E15: Brazil | F15: Norway | G15: Last 16
A16: 71syco9icpb3gpojexfq9sh04 | B16: Paraguay v France | C16: 46207 | D16: 21:00:00Z | E16: Paraguay | F16: France | G16: Last 16
A17: 1tfdd32vy6ouod43ek7l7kc9g | B17: Canada v Morocco | C17: 46207 | D17: 17:00:00Z | E17: Canada | F17: Morocco | G17: Last 16
A18: 3e05jx7evbp03r1yvu3ryg0t0 | B18: Colombia v Ghana | C18: 46207 | D18: 01:30:00Z | E18: Colombia | F18: Ghana | G18: Last 32
A19: c328g6toeflzg65gf28592olw | B19: Argentina vs Cabo Verde | C19: 46206 | D19: 22:00:00Z | E19: Argentina | F19: Cabo Verde | G19: Last 32
A20: etsoc4p3zsifly6xks7ossl5g | B20: Australia vs Egypt | C20: 46206 | D20: 18:00:00Z | E20: Australia | F20: Egypt | G20: Last 32
A21: 1pah6dqrmiqvtouxgbzlzoefo | B21: Switzerland v Algeria | C21: 46206 | D21: 03:00:00Z | E21: Switzerland | F21: Algeria | G21: Last 32
A22: a9a29jmg821rce6jl07v6rod0 | B22: Portugal v Croatia | C22: 46205 | D22: 23:00:00Z | E22: Portugal | F22: Croatia | G22: Last 32
A23: c26uegvn7o8d3uyb04tuuxjbo | B23: Spain v Austria | C23: 46205 | D23: 19:00:00Z | E23: Spain | F23: Austria | G23: Last 32
... A105: 4tcpns1nwyc0jtpucgzj9dp90 | B105: Mexico vs South Africa | C105: 46184 | D105: 19:00:00Z | E105: Mexico | F105: South Africa | G105: G1

Sheet PickedPlayers
A1: Round | B1: Pick | C1: Manager | D1: Player | E1: player_id | F1: Nation | G1: Position | H1: Total | I1: Bonus | J1: G1 | K1: G2 | L1: G3 | M1: Last 32 | N1: Last 16 | O1: Quarter Final | P1: Semi Final | Q1: 3rd Place / Final
A2: 1 | B2: 1 | C2: Barlow | D2: K. Mbappé | E2: 5e9ilgrz3tzg9kd1gk3yvrahh | F2: =IF(D2="","",VLOOKUP(D2,SquadLists!C:E,2,FALSE)) -> France | G2: =IF(D2="","",VLOOKUP(D2,SquadLists!C:E,3,FALSE)) -> FWD
A3: 1 | B3: 2 | C3: Taylor | D3: H. Kane | E3: b9g4qurpll4wizajo95c406hh | F3: =IF(D3="","",VLOOKUP(D3,SquadLists!C:E,2,FALSE)) -> England | G3: =IF(D3="","",VLOOKUP(D3,SquadLists!C:E,3,FALSE)) -> FWD
A4: 1 | B4: 3 | C4: Ian | D4: Mikel Oyarzabal | E4: b45ryclny991bm7qosieyg1cl | F4: =IF(D4="","",VLOOKUP(D4,SquadLists!C:E,2,FALSE)) -> Spain | G4: =IF(D4="","",VLOOKUP(D4,SquadLists!C:E,3,FALSE)) -> FWD
A5: 1 | B5: 4 | C5: Will T | D5: Lamine Yamal | E5: abr79wsl0folgkyvl821ggs2c | F5: =IF(D5="","",VLOOKUP(D5,SquadLists!C:E,2,FALSE)) -> Spain | G5: =IF(D5="","",VLOOKUP(D5,SquadLists!C:E,3,FALSE)) -> FWD
A6: 1 | B6: 5 | C6: Joe | D6: O. Dembélé | E6: ckaqxlw257qzj8vjdumvwbaad | F6: =IF(D6="","",VLOOKUP(D6,SquadLists!C:E,2,FALSE)) -> France | G6: =IF(D6="","",VLOOKUP(D6,SquadLists!C:E,3,FALSE)) -> FWD
A7: 1 | B7: 6 | C7: Dan | D7: L. Messi | E7: c5ryhn04g9goikd0blmh83aol | F7: =IF(D7="","",VLOOKUP(D7,SquadLists!C:E,2,FALSE)) -> Argentina | G7: =IF(D7="","",VLOOKUP(D7,SquadLists!C:E,3,FALSE)) -> FWD
A8: 1 | B8: 7 | C8: Andy | D8: Bruno Fernandes | E8: 3vtjjrqof5z2tjj84ehadqc45 | F8: =IF(D8="","",VLOOKUP(D8,SquadLists!C:E,2,FALSE)) -> Portugal | G8: =IF(D8="","",VLOOKUP(D8,SquadLists!C:E,3,FALSE)) -> MID
A9: 1 | B9: 8 | C9: Will S | D9: Cristiano Ronaldo | E9: h17s3qts1dz1zqjw19jazzkl | F9: =IF(D9="","",VLOOKUP(D9,SquadLists!C:E,2,FALSE)) -> Portugal | G9: =IF(D9="","",VLOOKUP(D9,SquadLists!C:E,3,FALSE)) -> FWD
A10: 2 | B10: 9 | C10: Will S | D10: K. Havertz | E10: ed20ebhqi5c32vbbsze8r6yuh | F10: =IF(D10="","",VLOOKUP(D10,SquadLists!C:E,2,FALSE)) -> Germany | G10: =IF(D10="","",VLOOKUP(D10,SquadLists!C:E,3,FALSE)) -> FWD
A11: 2 | B11: 10 | C11: Andy | D11: J. Alvarez | E11: 9ikkuxd19avliz1khcrm82gyy | F11: =IF(D11="","",VLOOKUP(D11,SquadLists!C:E,2,FALSE)) -> Argentina | G11: =IF(D11="","",VLOOKUP(D11,SquadLists!C:E,3,FALSE)) -> FWD
A12: 2 | B12: 11 | C12: Dan | D12: Raphinha | E12: 2wl6h1rlrfnn2mr65vuo3t815 | F12: =IF(D12="","",VLOOKUP(D12,SquadLists!C:E,2,FALSE)) -> Brazil | G12: =IF(D12="","",VLOOKUP(D12,SquadLists!C:E,3,FALSE)) -> FWD
A13: 2 | B13: 12 | C13: Joe | D13: Vinícius Júnior | E13: b4witgokm49tidm1a83qcvbop | F13: =IF(D13="","",VLOOKUP(D13,SquadLists!C:E,2,FALSE)) -> Brazil | G13: =IF(D13="","",VLOOKUP(D13,SquadLists!C:E,3,FALSE)) -> FWD
... A137: 17 | B137: 136 | C137: Dan | D137: F. Medina | E137: br7zigajqee6fms35zhm1sb8p | F137: =IF(D137="","",VLOOKUP(D137,SquadLists!C:E,2,FALSE)) -> Argentina | G137: =IF(D137="","",VLOOKUP(D137,SquadLists!C:E,3,FALSE)) -> DEF
A138: 18 | B138: 137 | F138: =IF(D138="","",VLOOKUP(D138,SquadLists!C:E,2,FALSE)) | G138: =IF(D138="","",VLOOKUP(D138,SquadLists!C:E,3,FALSE))
A139: 18 | B139: 138 | F139: =IF(D139="","",VLOOKUP(D139,SquadLists!C:E,2,FALSE)) | G139: =IF(D139="","",VLOOKUP(D139,SquadLists!C:E,3,FALSE))
A140: 18 | B140: 139 | F140: =IF(D140="","",VLOOKUP(D140,SquadLists!C:E,2,FALSE)) | G140: =IF(D140="","",VLOOKUP(D140,SquadLists!C:E,3,FALSE))
A141: 18 | B141: 140 | F141: =IF(D141="","",VLOOKUP(D141,SquadLists!C:E,2,FALSE)) | G141: =IF(D141="","",VLOOKUP(D141,SquadLists!C:E,3,FALSE))
A142: 18 | B142: 141 | F142: =IF(D142="","",VLOOKUP(D142,SquadLists!C:E,2,FALSE)) | G142: =IF(D142="","",VLOOKUP(D142,SquadLists!C:E,3,FALSE))
A143: 18 | B143: 142 | F143: =IF(D143="","",VLOOKUP(D143,SquadLists!C:E,2,FALSE)) | G143: =IF(D143="","",VLOOKUP(D143,SquadLists!C:E,3,FALSE))
A144: 18 | B144: 143 | F144: =IF(D144="","",VLOOKUP(D144,SquadLists!C:E,2,FALSE)) | G144: =IF(D144="","",VLOOKUP(D144,SquadLists!C:E,3,FALSE))
A145: 18 | B145: 144 | F145: =IF(D145="","",VLOOKUP(D145,SquadLists!C:E,2,FALSE)) | G145: =IF(D145="","",VLOOKUP(D145,SquadLists!C:E,3,FALSE))

Sheet OriginalPaste
A1: Goalkeeper | E1: =A1 -> Goalkeeper
A2: Goalkeeper | B2: Melvin Feyçal Mastil | C2: M. Mastil | D2: Algeria | E2: =A2 -> Goalkeeper | F2: Luca Zinedine Zidane Fernández | G2: L. Zidane | H2: Algeria
A3: Goalkeeper | B3: Oussama Benbot | C3: O. Benbot | D3: Algeria | E3: =A3 -> Goalkeeper
A4: Defender | E4: =A4 -> Defender
A5: Defender | B5: Aïssa Mandi | C5: A. Mandi | D5: Algeria | E5: =A5 -> Defender | F5: Rayan Aït-Nouri | G5: R. Aït-Nouri | H5: Algeria
A6: Defender | B6: Achref Abada | C6: A. Abada | D6: Algeria | E6: =A6 -> Defender | F6: Rafik Belghali | G6: R. Belghali | H6: Algeria
A7: Defender | B7: Mohamed Amine Tougai | C7: M. Tougai | D7: Algeria | E7: =A7 -> Defender | F7: Amir Selmane Ramy Bensebaini | G7: R. Bensebaini | H7: Algeria
A8: Defender | B8: Zineddine Belaïd | C8: Z. Belaïd | D8: Algeria | E8: =A8 -> Defender | F8: Samir Sophian Chergui | G8: S. Chergui | H8: Algeria
A9: Defender | B9: Jaouen Djimmy Hadjam | C9: J. Hadjam | D9: Algeria | E9: =A9 -> Defender
A10: Midfielder | E10: =A10 -> Midfielder
A11: Midfielder | B11: Ramiz Larbi Zerrouki | C11: R. Zerrouki | D11: Algeria | E11: =A11 -> Midfielder | F11: Nabil Bentaleb | G11: N. Bentaleb | H11: Algeria
A12: Midfielder | B12: Houssem-Eddine Chaâbane Aouar | C12: H. Aouar | D12: Algeria | E12: =A12 -> Midfielder | F12: Ibrahim Maza | G12: I. Maza | H12: Algeria
A13: Midfielder | B13: Farès Chaïbi | C13: F. Chaïbi | D13: Algeria | E13: =A13 -> Midfielder | F13: Yacine Mohammed El Ghazali Titraoui | G13: Y. Titraoui | H13: Algeria
A14: Midfielder | B14: Hicham Boudaoui | C14: H. Boudaoui | D14: Algeria | E14: =A14 -> Midfielder
A15: Forward | E15: =A15 -> Forward
A16: Forward | B16: Riyad Karim Mahrez | C16: R. Mahrez | D16: Algeria | E16: =A16 -> Forward | F16: Mohammed El Amine Amoura | G16: M. Amoura | H16: Algeria
A17: Forward | B17: Amine Ferid Gouiri | C17: A. Gouiri | D17: Algeria | E17: =A17 -> Forward | F17: Adil Boulbina | G17: A. Boulbina | H17: Algeria
A18: Forward | B18: Anis Hadj Moussa | C18: A. Hadj Moussa | D18: Algeria | E18: =A18 -> Forward | F18: Farès Ghedjemis | G18: F. Ghedjemis | H18: Algeria
A19: Forward | B19: Ahmed Nadhir Benbouali | C19: N. Benbouali | D19: Algeria | E19: =A19 -> Forward
A20: Goalkeeper | E20: =A20 -> Goalkeeper
A21: Goalkeeper | B21: Juan Agustín Musso | C21: J. Musso | D21: Argentina | E21: =A21 -> Goalkeeper | F21: Emiliano Martínez | G21: E. Martínez | H21: Argentina
A22: Goalkeeper | B22: Gerónimo Rulli | C22: G. Rulli | D22: Argentina | E22: =A22 -> Goalkeeper
A23: Defender | E23: =A23 -> Defender
A24: Defender | B24: Nicolás Alejandro Tagliafico | C24: N. Tagliafico | D24: Argentina | E24: =A24 -> Defender | F24: Nicolás Hernán Gonzalo Otamendi | G24: N. Otamendi | H24: Argentina
A25: Defender | B25: Gonzalo Ariel Montiel | C25: G. Montiel | D25: Argentina | E25: =A25 -> Defender | F25: Facundo Axel Medina | G25: F. Medina | H25: Argentina
A26: Defender | B26: Lisandro Martínez | C26: Lisandro Martínez | D26: Argentina | E26: =A26 -> Defender | F26: Nahuel Molina Lucero | G26: N. Molina | H26: Argentina
A27: Defender | B27: Cristian Gabriel Romero | C27: C. Romero | D27: Argentina | E27: =A27 -> Defender
A28: Midfielder | E28: =A28 -> Midfielder
A29: Midfielder | B29: Leandro Daniel Paredes | C29: L. Paredes | D29: Argentina | E29: =A29 -> Midfielder | F29: Exequiel Alejandro Palacios | G29: E. Palacios | H29: Argentina
A30: Midfielder | B30: Rodrigo Javier De Paul | C30: R. De Paul | D30: Argentina | E30: =A30 -> Midfielder | F30: Thiago Ezequiel Almada | G30: T. Almada | H30: Argentina
A31: Midfielder | B31: Valentín Barco | C31: V. Barco | D31: Argentina | E31: =A31 -> Midfielder | F31: Alexis Mac Allister | G31: A. Mac Allister | H31: Argentina
A32: Midfielder | B32: Giovani Lo Celso | C32: G. Lo Celso | D32: Argentina | E32: =A32 -> Midfielder | F32: Enzo Jeremías Fernández | G32: E. Fernández | H32: Argentina
A33: Forward | E33: =A33 -> Forward
A34: Forward | B34: Julián Alvarez | C34: J. Alvarez | D34: Argentina | E34: =A34 -> Forward | F34: Nicolás Paz Martínez | G34: N. Paz | H34: Argentina
A35: Forward | B35: Lionel Andrés Messi Cuccittini | C35: L. Messi | D35: Argentina | E35: =A35 -> Forward | F35: José Manuel Alberto López | G35: J. López | H35: Argentina
A36: Forward | B36: Nicolás Iván González | C36: N. González | D36: Argentina | E36: =A36 -> Forward | F36: Lautaro Martínez | G36: Lautaro Martínez | H36: Argentina
A37: Forward | B37: Giuliano Simeone Baldini | C37: G. Simeone | D37: Argentina | E37: =A37 -> Forward
A38: Goalkeeper | E38: =A38 -> Goalkeeper
A39: Goalkeeper | B39: Mathew David Ryan | C39: M. Ryan | D39: Australia | E39: =A39 -> Goalkeeper | F39: Patrick Thomas Beach | G39: P. Beach | H39: Australia
A40: Goalkeeper | B40: Paul David Izzo | C40: P. Izzo | D40: Australia | E40: =A40 -> Goalkeeper
...

Sheet Teams
B2: Barlow | F2: Taylor | J2: Ian | N2: Will T
B3: Player | C3: Pos | D3: Nationality | F3: Player | G3: Pos | H3: Nationality | J3: Player | K3: Pos | L3: Nationality | N3: Player | O3: Pos | P3: Nationality
B4: K. Mbappé | C4: =VLOOKUP(B4,PickedPlayers!D:G,4,FALSE) -> FWD | D4: =VLOOKUP(B4,PickedPlayers!D:G,3,FALSE) -> France | F4: H. Kane | G4: =VLOOKUP(F4,PickedPlayers!D:G,4,FALSE) -> FWD | H4: =VLOOKUP(F4,PickedPlayers!D:G,3,FALSE) -> England | J4: Mikel Oyarzabal | K4: =VLOOKUP(J4,PickedPlayers!D:G,4,FALSE) -> FWD | L4: =VLOOKUP(J4,PickedPlayers!D:G,3,FALSE) -> Spain | N4: Lamine Yamal | O4: =VLOOKUP(N4,PickedPlayers!D:G,4,FALSE) -> FWD | P4: =VLOOKUP(N4,PickedPlayers!D:G,3,FALSE) -> Spain
B5: J. Bellingham | C5: =VLOOKUP(B5,PickedPlayers!D:G,4,FALSE) -> MID | D5: =VLOOKUP(B5,PickedPlayers!D:G,3,FALSE) -> England | F5: S. McTominay | G5: =VLOOKUP(F5,PickedPlayers!D:G,4,FALSE) -> MID | H5: =VLOOKUP(F5,PickedPlayers!D:G,3,FALSE) -> Scotland | J5: M. Olise | K5: =VLOOKUP(J5,PickedPlayers!D:G,4,FALSE) -> MID | L5: =VLOOKUP(J5,PickedPlayers!D:G,3,FALSE) -> France | N5: E. Haaland | O5: =VLOOKUP(N5,PickedPlayers!D:G,4,FALSE) -> FWD | P5: =VLOOKUP(N5,PickedPlayers!D:G,3,FALSE) -> Norway
B6: K. De Bruyne | C6: =VLOOKUP(B6,PickedPlayers!D:G,4,FALSE) -> MID | D6: =VLOOKUP(B6,PickedPlayers!D:G,3,FALSE) -> Belgium | F6: J. Doku | G6: =VLOOKUP(F6,PickedPlayers!D:G,4,FALSE) -> FWD | H6: =VLOOKUP(F6,PickedPlayers!D:G,3,FALSE) -> Belgium | J6: F. Wirtz | K6: =VLOOKUP(J6,PickedPlayers!D:G,4,FALSE) -> MID | L6: =VLOOKUP(J6,PickedPlayers!D:G,3,FALSE) -> Germany | N6: E. Fernández | O6: =VLOOKUP(N6,PickedPlayers!D:G,4,FALSE) -> MID | P6: =VLOOKUP(N6,PickedPlayers!D:G,3,FALSE) -> Argentina
B7: T. Hernández | C7: =VLOOKUP(B7,PickedPlayers!D:G,4,FALSE) -> DEF | D7: =VLOOKUP(B7,PickedPlayers!D:G,3,FALSE) -> France | F7: J. Pickford | G7: =VLOOKUP(F7,PickedPlayers!D:G,4,FALSE) -> GK | H7: =VLOOKUP(F7,PickedPlayers!D:G,3,FALSE) -> England | J7: A. Hakimi | K7: =VLOOKUP(J7,PickedPlayers!D:G,4,FALSE) -> DEF | L7: =VLOOKUP(J7,PickedPlayers!D:G,3,FALSE) -> Morocco | N7: Pedri | O7: =VLOOKUP(N7,PickedPlayers!D:G,4,FALSE) -> MID | P7: =VLOOKUP(N7,PickedPlayers!D:G,3,FALSE) -> Spain
B8: João Cancelo | C8: =VLOOKUP(B8,PickedPlayers!D:G,4,FALSE) -> DEF | D8: =VLOOKUP(B8,PickedPlayers!D:G,3,FALSE) -> Portugal | F8: Nico Williams | G8: =VLOOKUP(F8,PickedPlayers!D:G,4,FALSE) -> FWD | H8: =VLOOKUP(F8,PickedPlayers!D:G,3,FALSE) -> Spain | J8: Unai Simón | K8: =VLOOKUP(J8,PickedPlayers!D:G,4,FALSE) -> GK | L8: =VLOOKUP(J8,PickedPlayers!D:G,3,FALSE) -> Spain | N8: N. O'Reilly | O8: =VLOOKUP(N8,PickedPlayers!D:G,4,FALSE) -> DEF | P8: =VLOOKUP(N8,PickedPlayers!D:G,3,FALSE) -> England
B9: Lautaro Martínez | C9: =VLOOKUP(B9,PickedPlayers!D:G,4,FALSE) -> FWD | D9: =VLOOKUP(B9,PickedPlayers!D:G,3,FALSE) -> Argentina | F9: W. Saliba | G9: =VLOOKUP(F9,PickedPlayers!D:G,4,FALSE) -> DEF | H9: =VLOOKUP(F9,PickedPlayers!D:G,3,FALSE) -> France | J9: Marc Cucurella | K9: =VLOOKUP(J9,PickedPlayers!D:G,4,FALSE) -> DEF | L9: =VLOOKUP(J9,PickedPlayers!D:G,3,FALSE) -> Spain | N9: Alisson Becker | O9: =VLOOKUP(N9,PickedPlayers!D:G,4,FALSE) -> GK | P9: =VLOOKUP(N9,PickedPlayers!D:G,3,FALSE) -> Brazil
B10: F. Valverde | C10: =VLOOKUP(B10,PickedPlayers!D:G,4,FALSE) -> MID | D10: =VLOOKUP(B10,PickedPlayers!D:G,3,FALSE) -> Uruguay | F10: C. Pulisic | G10: =VLOOKUP(F10,PickedPlayers!D:G,4,FALSE) -> MID | H10: =VLOOKUP(F10,PickedPlayers!D:G,3,FALSE) -> USA | J10: V. Gyökeres | K10: =VLOOKUP(J10,PickedPlayers!D:G,4,FALSE) -> FWD | L10: =VLOOKUP(J10,PickedPlayers!D:G,3,FALSE) -> Sweden | N10: D. Raum | O10: =VLOOKUP(N10,PickedPlayers!D:G,4,FALSE) -> DEF | P10: =VLOOKUP(N10,PickedPlayers!D:G,3,FALSE) -> Germany
B11: Alejandro Grimaldo | C11: =VLOOKUP(B11,PickedPlayers!D:G,4,FALSE) -> DEF | D11: =VLOOKUP(B11,PickedPlayers!D:G,3,FALSE) -> Spain | F11: Matheus Cunha | G11: =VLOOKUP(F11,PickedPlayers!D:G,4,FALSE) -> FWD | H11: =VLOOKUP(F11,PickedPlayers!D:G,3,FALSE) -> Brazil | J11: J. Gvardiol | K11: =VLOOKUP(J11,PickedPlayers!D:G,4,FALSE) -> DEF | L11: =VLOOKUP(J11,PickedPlayers!D:G,3,FALSE) -> Croatia | N11: E. Anderson | O11: =VLOOKUP(N11,PickedPlayers!D:G,4,FALSE) -> MID | P11: =VLOOKUP(N11,PickedPlayers!D:G,3,FALSE) -> England
B12: D. Núñez | C12: =VLOOKUP(B12,PickedPlayers!D:G,4,FALSE) -> FWD | D12: =VLOOKUP(B12,PickedPlayers!D:G,3,FALSE) -> Uruguay | F12: M. Ødegaard | G12: =VLOOKUP(F12,PickedPlayers!D:G,4,FALSE) -> MID | H12: =VLOOKUP(F12,PickedPlayers!D:G,3,FALSE) -> Norway | J12: Bernardo Silva | K12: =VLOOKUP(J12,PickedPlayers!D:G,4,FALSE) -> MID | L12: =VLOOKUP(J12,PickedPlayers!D:G,3,FALSE) -> Portugal | N12: A. Tchouaméni | O12: =VLOOKUP(N12,PickedPlayers!D:G,4,FALSE) -> MID | P12: =VLOOKUP(N12,PickedPlayers!D:G,3,FALSE) -> France
B13: A. Rüdiger | C13: =VLOOKUP(B13,PickedPlayers!D:G,4,FALSE) -> DEF | D13: =VLOOKUP(B13,PickedPlayers!D:G,3,FALSE) -> Germany | F13: A. Güler | G13: =VLOOKUP(F13,PickedPlayers!D:G,4,FALSE) -> MID | H13: =VLOOKUP(F13,PickedPlayers!D:G,3,FALSE) -> Turkey | J13: Son Heung-Min | K13: =VLOOKUP(J13,PickedPlayers!D:G,4,FALSE) -> FWD | L13: =VLOOKUP(J13,PickedPlayers!D:G,3,FALSE) -> South Korea | N13: D. Ndoye | O13: =VLOOKUP(N13,PickedPlayers!D:G,4,FALSE) -> FWD | P13: =VLOOKUP(N13,PickedPlayers!D:G,3,FALSE) -> Switzerland
B14: J. Stones | C14: =VLOOKUP(B14,PickedPlayers!D:G,4,FALSE) -> DEF | D14: =VLOOKUP(B14,PickedPlayers!D:G,3,FALSE) -> England | F14: A. Robinson | G14: =VLOOKUP(F14,PickedPlayers!D:G,4,FALSE) -> DEF | H14: =VLOOKUP(F14,PickedPlayers!D:G,3,FALSE) -> USA | J14: R. James | K14: =VLOOKUP(J14,PickedPlayers!D:G,4,FALSE) -> DEF | L14: =VLOOKUP(J14,PickedPlayers!D:G,3,FALSE) -> England | N14: Marquinhos | O14: =VLOOKUP(N14,PickedPlayers!D:G,4,FALSE) -> DEF | P14: =VLOOKUP(N14,PickedPlayers!D:G,3,FALSE) -> Brazil
B15: L. Trossard | C15: =VLOOKUP(B15,PickedPlayers!D:G,4,FALSE) -> FWD | D15: =VLOOKUP(B15,PickedPlayers!D:G,3,FALSE) -> Belgium | F15: L. Vušković | G15: =VLOOKUP(F15,PickedPlayers!D:G,4,FALSE) -> DEF | H15: =VLOOKUP(F15,PickedPlayers!D:G,3,FALSE) -> Croatia | J15: M. van de Ven | K15: =VLOOKUP(J15,PickedPlayers!D:G,4,FALSE) -> DEF | L15: =VLOOKUP(J15,PickedPlayers!D:G,3,FALSE) -> Netherlands | N15: Rúben Dias | O15: =VLOOKUP(N15,PickedPlayers!D:G,4,FALSE) -> DEF | P15: =VLOOKUP(N15,PickedPlayers!D:G,3,FALSE) -> Portugal
... B19: Y. Bounou | C19: =VLOOKUP(B19,PickedPlayers!D:G,4,FALSE) -> GK | D19: =VLOOKUP(B19,PickedPlayers!D:G,3,FALSE) -> Morocco | F19: D. Muñoz | G19: =VLOOKUP(F19,PickedPlayers!D:G,4,FALSE) -> DEF | H19: =VLOOKUP(F19,PickedPlayers!D:G,3,FALSE) -> Colombia | J19: D. Livaković | K19: =VLOOKUP(J19,PickedPlayers!D:G,4,FALSE) -> GK | L19: =VLOOKUP(J19,PickedPlayers!D:G,3,FALSE) -> Croatia | N19: R. Mofokeng | O19: =VLOOKUP(N19,PickedPlayers!D:G,4,FALSE) -> FWD | P19: =VLOOKUP(N19,PickedPlayers!D:G,3,FALSE) -> South Africa
C21: Total | D21: Max | G21: Total | H21: Max | K21: Total | L21: Max | O21: Total | P21: Max
B22: GK | C22: =COUNTIF(C4:C19,"GK") -> 2 | D22: 2 | F22: GK | G22: =COUNTIF(G4:G19,"GK") -> 2 | H22: 2 | J22: GK | K22: =COUNTIF(K4:K19,"GK") -> 2 | L22: 2 | N22: GK | O22: =COUNTIF(O4:O19,"GK") -> 2 | P22: 2
B23: DEF | C23: =COUNTIF(C4:C19,"DEF") -> 5 | D23: 5 | F23: DEF | G23: =COUNTIF(G4:G19,"DEF") -> 5 | H23: 5 | J23: DEF | K23: =COUNTIF(K4:K19,"DEF") -> 5 | L23: 5 | N23: DEF | O23: =COUNTIF(O4:O19,"DEF") -> 5 | P23: 5
B24: MID | C24: =COUNTIF(C4:C19,"MID") -> 4 | D24: 5* | F24: MID | G24: =COUNTIF(G4:G19,"MID") -> 4 | H24: 5* | J24: MID | K24: =COUNTIF(K4:K19,"MID") -> 5 | L24: 5* | N24: MID | O24: =COUNTIF(O4:O19,"MID") -> 4 | P24: 5*
B25: FWD | C25: =COUNTIF(C4:C19,"FWD") -> 5 | D25: 5* | F25: FWD | G25: =COUNTIF(G4:G19,"FWD") -> 5 | H25: 5* | J25: FWD | K25: =COUNTIF(K4:K19,"FWD") -> 4 | L25: 5* | N25: FWD | O25: =COUNTIF(O4:O19,"FWD") -> 5 | P25: 5*
B27: Joe | F27: Dan | J27: Andy | N27: Will S
B28: Player | C28: Pos | D28: Nationality | F28: Player | G28: Pos | H28: Nationality | J28: Player | K28: Pos | L28: Nationality | N28: Player | O28: Pos | P28: Nationality
B29: O. Dembélé | C29: =VLOOKUP(B29,PickedPlayers!D:G,4,FALSE) -> FWD | D29: =VLOOKUP(B29,PickedPlayers!D:G,3,FALSE) -> France | F29: L. Messi | G29: =VLOOKUP(F29,PickedPlayers!D:G,4,FALSE) -> FWD | H29: =VLOOKUP(F29,PickedPlayers!D:G,3,FALSE) -> Argentina | J29: Bruno Fernandes | K29: =VLOOKUP(J29,PickedPlayers!D:G,4,FALSE) -> MID | L29: =VLOOKUP(J29,PickedPlayers!D:G,3,FALSE) -> Portugal | N29: Cristiano Ronaldo | O29: =VLOOKUP(N29,PickedPlayers!D:G,4,FALSE) -> FWD | P29: =VLOOKUP(N29,PickedPlayers!D:G,3,FALSE) -> Portugal
B30: Vinícius Júnior | C30: =VLOOKUP(B30,PickedPlayers!D:G,4,FALSE) -> FWD | D30: =VLOOKUP(B30,PickedPlayers!D:G,3,FALSE) -> Brazil | F30: Raphinha | G30: =VLOOKUP(F30,PickedPlayers!D:G,4,FALSE) -> FWD | H30: =VLOOKUP(F30,PickedPlayers!D:G,3,FALSE) -> Brazil | J30: J. Alvarez | K30: =VLOOKUP(J30,PickedPlayers!D:G,4,FALSE) -> FWD | L30: =VLOOKUP(J30,PickedPlayers!D:G,3,FALSE) -> Argentina | N30: K. Havertz | O30: =VLOOKUP(N30,PickedPlayers!D:G,4,FALSE) -> FWD | P30: =VLOOKUP(N30,PickedPlayers!D:G,3,FALSE) -> Germany
B31: Gabriel Magalhães | C31: =VLOOKUP(B31,PickedPlayers!D:G,4,FALSE) -> DEF | D31: =VLOOKUP(B31,PickedPlayers!D:G,3,FALSE) -> Brazil | F31: L. Sané | G31: =VLOOKUP(F31,PickedPlayers!D:G,4,FALSE) -> FWD | H31: =VLOOKUP(F31,PickedPlayers!D:G,3,FALSE) -> Germany | J31: B. Saka | K31: =VLOOKUP(J31,PickedPlayers!D:G,4,FALSE) -> FWD | L31: =VLOOKUP(J31,PickedPlayers!D:G,3,FALSE) -> England | N31: J. Musiala | O31: =VLOOKUP(N31,PickedPlayers!D:G,4,FALSE) -> MID | P31: =VLOOKUP(N31,PickedPlayers!D:G,3,FALSE) -> Germany
B32: T. Courtois | C32: =VLOOKUP(B32,PickedPlayers!D:G,4,FALSE) -> GK | D32: =VLOOKUP(B32,PickedPlayers!D:G,3,FALSE) -> Belgium | F32: J. Kimmich | G32: =VLOOKUP(F32,PickedPlayers!D:G,4,FALSE) -> MID | H32: =VLOOKUP(F32,PickedPlayers!D:G,3,FALSE) -> Germany | J32: E. Martínez | K32: =VLOOKUP(J32,PickedPlayers!D:G,4,FALSE) -> GK | L32: =VLOOKUP(J32,PickedPlayers!D:G,3,FALSE) -> Argentina | N32: R. Cherki | O32: =VLOOKUP(N32,PickedPlayers!D:G,4,FALSE) -> MID | P32: =VLOOKUP(N32,PickedPlayers!D:G,3,FALSE) -> France
B33: M. Guéhi | C33: =VLOOKUP(B33,PickedPlayers!D:G,4,FALSE) -> DEF | D33: =VLOOKUP(B33,PickedPlayers!D:G,3,FALSE) -> England | F33: D. Doué | G33: =VLOOKUP(F33,PickedPlayers!D:G,4,FALSE) -> FWD | H33: =VLOOKUP(F33,PickedPlayers!D:G,3,FALSE) -> France | J33: L. Díaz | K33: =VLOOKUP(J33,PickedPlayers!D:G,4,FALSE) -> FWD | L33: =VLOOKUP(J33,PickedPlayers!D:G,3,FALSE) -> Colombia | N33: J. Koundé | O33: =VLOOKUP(N33,PickedPlayers!D:G,4,FALSE) -> DEF | P33: =VLOOKUP(N33,PickedPlayers!D:G,3,FALSE) -> France
B34: Rafael Leão | C34: =VLOOKUP(B34,PickedPlayers!D:G,4,FALSE) -> FWD | D34: =VLOOKUP(B34,PickedPlayers!D:G,3,FALSE) -> Portugal | F34: M. Maignan | G34: =VLOOKUP(F34,PickedPlayers!D:G,4,FALSE) -> GK | H34: =VLOOKUP(F34,PickedPlayers!D:G,3,FALSE) -> France | J34: V. van Dijk | K34: =VLOOKUP(J34,PickedPlayers!D:G,4,FALSE) -> DEF | L34: =VLOOKUP(J34,PickedPlayers!D:G,3,FALSE) -> Netherlands | N34: Nuno Mendes | O34: =VLOOKUP(N34,PickedPlayers!D:G,4,FALSE) -> DEF | P34: =VLOOKUP(N34,PickedPlayers!D:G,3,FALSE) -> Portugal
B35: D. Rice | C35: =VLOOKUP(B35,PickedPlayers!D:G,4,FALSE) -> MID | D35: =VLOOKUP(B35,PickedPlayers!D:G,3,FALSE) -> England | F35: Aymeric Laporte | G35: =VLOOKUP(F35,PickedPlayers!D:G,4,FALSE) -> DEF | H35: =VLOOKUP(F35,PickedPlayers!D:G,3,FALSE) -> Spain | J35: Rodri | K35: =VLOOKUP(J35,PickedPlayers!D:G,4,FALSE) -> MID | L35: =VLOOKUP(J35,PickedPlayers!D:G,3,FALSE) -> Spain | N35: M. Neuer | O35: =VLOOKUP(N35,PickedPlayers!D:G,4,FALSE) -> GK | P35: =VLOOKUP(N35,PickedPlayers!D:G,3,FALSE) -> Germany
B36: Marcos Llorente | C36: =VLOOKUP(B36,PickedPlayers!D:G,4,FALSE) -> MID | D36: =VLOOKUP(B36,PickedPlayers!D:G,3,FALSE) -> Spain | F36: Bruno Guimarães | G36: =VLOOKUP(F36,PickedPlayers!D:G,4,FALSE) -> MID | H36: =VLOOKUP(F36,PickedPlayers!D:G,3,FALSE) -> Brazil | J36: Pedro Porro | K36: =VLOOKUP(J36,PickedPlayers!D:G,4,FALSE) -> DEF | L36: =VLOOKUP(J36,PickedPlayers!D:G,3,FALSE) -> Spain | N36: C. Gakpo | O36: =VLOOKUP(N36,PickedPlayers!D:G,4,FALSE) -> FWD | P36: =VLOOKUP(N36,PickedPlayers!D:G,3,FALSE) -> Netherlands
B37: Alex Sandro | C37: =VLOOKUP(B37,PickedPlayers!D:G,4,FALSE) -> DEF | D37: =VLOOKUP(B37,PickedPlayers!D:G,3,FALSE) -> Brazil | F37: N. Tagliafico | G37: =VLOOKUP(F37,PickedPlayers!D:G,4,FALSE) -> DEF | H37: =VLOOKUP(F37,PickedPlayers!D:G,3,FALSE) -> Argentina | J37: Mohamed Salah | K37: =VLOOKUP(J37,PickedPlayers!D:G,4,FALSE) -> FWD | L37: =VLOOKUP(J37,PickedPlayers!D:G,3,FALSE) -> Egypt | N37: A. Mac Allister | O37: =VLOOKUP(N37,PickedPlayers!D:G,4,FALSE) -> MID | P37: =VLOOKUP(N37,PickedPlayers!D:G,3,FALSE) -> Argentina
B38: B. Díaz | C38: =VLOOKUP(B38,PickedPlayers!D:G,4,FALSE) -> MID | D38: =VLOOKUP(B38,PickedPlayers!D:G,3,FALSE) -> Morocco | F38: João Neves | G38: =VLOOKUP(F38,PickedPlayers!D:G,4,FALSE) -> MID | H38: =VLOOKUP(F38,PickedPlayers!D:G,3,FALSE) -> Portugal | J38: M. De Cuyper | K38: =VLOOKUP(J38,PickedPlayers!D:G,4,FALSE) -> DEF | L38: =VLOOKUP(J38,PickedPlayers!D:G,3,FALSE) -> Belgium | N38: D. Dumfries | O38: =VLOOKUP(N38,PickedPlayers!D:G,4,FALSE) -> DEF | P38: =VLOOKUP(N38,PickedPlayers!D:G,3,FALSE) -> Netherlands
B39: S. Mané | C39: =VLOOKUP(B39,PickedPlayers!D:G,4,FALSE) -> FWD | D39: =VLOOKUP(B39,PickedPlayers!D:G,3,FALSE) -> Senegal | F39: Y. Tielemans | G39: =VLOOKUP(F39,PickedPlayers!D:G,4,FALSE) -> MID | H39: =VLOOKUP(F39,PickedPlayers!D:G,3,FALSE) -> Belgium | J39: E. Konsa | K39: =VLOOKUP(J39,PickedPlayers!D:G,4,FALSE) -> DEF | L39: =VLOOKUP(J39,PickedPlayers!D:G,3,FALSE) -> England | N39: C. Romero | O39: =VLOOKUP(N39,PickedPlayers!D:G,4,FALSE) -> DEF | P39: =VLOOKUP(N39,PickedPlayers!D:G,3,FALSE) -> Argentina
B40: D. Upamecano | C40: =VLOOKUP(B40,PickedPlayers!D:G,4,FALSE) -> DEF | D40: =VLOOKUP(B40,PickedPlayers!D:G,3,FALSE) -> France | F40: Diogo Costa | G40: =VLOOKUP(F40,PickedPlayers!D:G,4,FALSE) -> GK | H40: =VLOOKUP(F40,PickedPlayers!D:G,3,FALSE) -> Portugal | J40: F. de Jong | K40: =VLOOKUP(J40,PickedPlayers!D:G,4,FALSE) -> MID | L40: =VLOOKUP(J40,PickedPlayers!D:G,3,FALSE) -> Netherlands | N40: Pau Cubarsí | O40: =VLOOKUP(N40,PickedPlayers!D:G,4,FALSE) -> DEF | P40: =VLOOKUP(N40,PickedPlayers!D:G,3,FALSE) -> Spain
... B44: David Raya | C44: =VLOOKUP(B44,PickedPlayers!D:G,4,FALSE) -> GK | D44: =VLOOKUP(B44,PickedPlayers!D:G,3,FALSE) -> Spain | F44: Danilo | G44: =VLOOKUP(F44,PickedPlayers!D:G,4,FALSE) -> DEF | H44: =VLOOKUP(F44,PickedPlayers!D:G,3,FALSE) -> Brazil | J44: I. Sangaré | K44: =VLOOKUP(J44,PickedPlayers!D:G,4,FALSE) -> MID | L44: =VLOOKUP(J44,PickedPlayers!D:G,3,FALSE) -> Ivory Coast | N44: R. Lukaku | O44: =VLOOKUP(N44,PickedPlayers!D:G,4,FALSE) -> FWD | P44: =VLOOKUP(N44,PickedPlayers!D:G,3,FALSE) -> Belgium
C46: Total | D46: Max | G46: Total | H46: Max | K46: Total | L46: Max | O46: Total | P46: Max
B47: GK | C47: =COUNTIF(C29:C44,"GK") -> 2 | D47: 2 | F47: GK | G47: =COUNTIF(G29:G44,"GK") -> 2 | H47: 2 | J47: GK | K47: =COUNTIF(K29:K44,"GK") -> 2 | L47: 2 | N47: GK | O47: =COUNTIF(O29:O44,"GK") -> 2 | P47: 2
B48: DEF | C48: =COUNTIF(C29:C44,"DEF") -> 5 | D48: 5 | F48: DEF | G48: =COUNTIF(G29:G44,"DEF") -> 5 | H48: 5 | J48: DEF | K48: =COUNTIF(K29:K44,"DEF") -> 5 | L48: 5 | N48: DEF | O48: =COUNTIF(O29:O44,"DEF") -> 5 | P48: 5
B49: MID | C49: =COUNTIF(C29:C44,"MID") -> 4 | D49: 5* | F49: MID | G49: =COUNTIF(G29:G44,"MID") -> 4 | H49: 5* | J49: MID | K49: =COUNTIF(K29:K44,"MID") -> 4 | L49: 5* | N49: MID | O49: =COUNTIF(O29:O44,"MID") -> 4 | P49: 5*
B50: FWD | C50: =COUNTIF(C29:C44,"FWD") -> 5 | D50: 5* | F50: FWD | G50: =COUNTIF(G29:G44,"FWD") -> 5 | H50: 5* | J50: FWD | K50: =COUNTIF(K29:K44,"FWD") -> 5 | L50: 5* | N50: FWD | O50: =COUNTIF(O29:O44,"FWD") -> 5 | P50: 5*

Sheet Barlow
A1: 1 Captain 1 Sub | D1: Group (1) | G1: Group (2) | J1: Group (3) | M1: Last 32 | P1: Last 16 | S1: Quarter Final | V1: Semi Final | Y1: 3rd Place / Final
A2: Position | B2: Player | C2: Nationality | D2: Opposition | E2: Selection | F2: Points | G2: Opposition | H2: Selection | I2: Points | J2: Opposition | K2: Selection | L2: Points | M2: Opposition | N2: Selection | O2: Points | P2: Opposition | Q2: Selection | R2: Points | S2: Opposition | T2: Selection | U2: Points | V2: Opposition | W2: Selection | X2: Points | Y2: Opposition | Z2: Selection | AA2: Points
A3: GK | B3: Ederson | C3: Brazil | D3: =VLOOKUP($C3,Fixtures!A:I,2,FALSE) -> MOR | E3: Subbed Off | F3: =VLOOKUP($B3,PickedPlayers!D:Q,7,FALSE) -> 0 | G3: =VLOOKUP($C3,Fixtures!A:I,3,FALSE) -> HAI | H3: Sub GK | I3: =VLOOKUP($B3,PickedPlayers!D:Q,8,FALSE) -> 0 | J3: =VLOOKUP($C3,Fixtures!A:I,4,FALSE) -> SCO | K3: Sub GK | L3: =VLOOKUP($B3,PickedPlayers!D:Q,9,FALSE) -> 0 | M3: =VLOOKUP($C3,Fixtures!A:I,5,FALSE) -> JAP | N3: Sub GK | O3: =VLOOKUP($B3,PickedPlayers!D:Q,10,FALSE) -> 0 | P3: =VLOOKUP($C3,Fixtures!A:I,6,FALSE) -> NOR | R3: =VLOOKUP($B3,PickedPlayers!D:Q,11,FALSE) -> 0 | S3: =VLOOKUP($C3,Fixtures!A:I,7,FALSE) -> TBC | U3: =VLOOKUP($B3,PickedPlayers!D:Q,12,FALSE) -> 0 | V3: =VLOOKUP($C3,Fixtures!A:I,8,FALSE) -> TBC | X3: =VLOOKUP($B3,PickedPlayers!D:Q,13,FALSE) -> 0 | Y3: =VLOOKUP($C3,Fixtures!A:I,9,FALSE) -> TBC | AA3: =VLOOKUP($B3,PickedPlayers!D:Q,14,FALSE) -> 0
A4: GK | B4: Y. Bounou | C4: Morocco | D4: =VLOOKUP($C4,Fixtures!A:I,2,FALSE) -> BRA | E4: Picked | F4: =VLOOKUP($B4,PickedPlayers!D:Q,7,FALSE) -> 0 | G4: =VLOOKUP($C4,Fixtures!A:I,3,FALSE) -> SCO | H4: Picked | I4: =VLOOKUP($B4,PickedPlayers!D:Q,8,FALSE) -> 0 | J4: =VLOOKUP($C4,Fixtures!A:I,4,FALSE) -> HAI | K4: Picked | L4: =VLOOKUP($B4,PickedPlayers!D:Q,9,FALSE) -> 0 | M4: =VLOOKUP($C4,Fixtures!A:I,5,FALSE) -> NED | N4: Picked | O4: =VLOOKUP($B4,PickedPlayers!D:Q,10,FALSE) -> 0 | P4: =VLOOKUP($C4,Fixtures!A:I,6,FALSE) -> CAN | R4: =VLOOKUP($B4,PickedPlayers!D:Q,11,FALSE) -> 0 | S4: =VLOOKUP($C4,Fixtures!A:I,7,FALSE) -> TBC | U4: =VLOOKUP($B4,PickedPlayers!D:Q,12,FALSE) -> 0 | V4: =VLOOKUP($C4,Fixtures!A:I,8,FALSE) -> TBC | X4: =VLOOKUP($B4,PickedPlayers!D:Q,13,FALSE) -> 0 | Y4: =VLOOKUP($C4,Fixtures!A:I,9,FALSE) -> TBC | AA4: =VLOOKUP($B4,PickedPlayers!D:Q,14,FALSE) -> 0
A5: DEF | B5: T. Hernández | C5: France | D5: =VLOOKUP($C5,Fixtures!A:I,2,FALSE) -> SEN | E5: Picked | F5: =VLOOKUP($B5,PickedPlayers!D:Q,7,FALSE) -> 0 | G5: =VLOOKUP($C5,Fixtures!A:I,3,FALSE) -> IRQ | H5: Picked | I5: =VLOOKUP($B5,PickedPlayers!D:Q,8,FALSE) -> 0 | J5: =VLOOKUP($C5,Fixtures!A:I,4,FALSE) -> NOR | K5: Picked | L5: =VLOOKUP($B5,PickedPlayers!D:Q,9,FALSE) -> 0 | M5: =VLOOKUP($C5,Fixtures!A:I,5,FALSE) -> SWE | N5: Picked | O5: =VLOOKUP($B5,PickedPlayers!D:Q,10,FALSE) -> 0 | P5: =VLOOKUP($C5,Fixtures!A:I,6,FALSE) -> PAR | R5: =VLOOKUP($B5,PickedPlayers!D:Q,11,FALSE) -> 0 | S5: =VLOOKUP($C5,Fixtures!A:I,7,FALSE) -> TBC | U5: =VLOOKUP($B5,PickedPlayers!D:Q,12,FALSE) -> 0 | V5: =VLOOKUP($C5,Fixtures!A:I,8,FALSE) -> TBC | X5: =VLOOKUP($B5,PickedPlayers!D:Q,13,FALSE) -> 0 | Y5: =VLOOKUP($C5,Fixtures!A:I,9,FALSE) -> TBC | AA5: =VLOOKUP($B5,PickedPlayers!D:Q,14,FALSE) -> 0
A6: DEF | B6: João Cancelo | C6: Portugal | D6: =VLOOKUP($C6,Fixtures!A:I,2,FALSE) -> CON | E6: Picked | F6: =VLOOKUP($B6,PickedPlayers!D:Q,7,FALSE) -> 0 | G6: =VLOOKUP($C6,Fixtures!A:I,3,FALSE) -> UZB | H6: Picked | I6: =VLOOKUP($B6,PickedPlayers!D:Q,8,FALSE) -> 0 | J6: =VLOOKUP($C6,Fixtures!A:I,4,FALSE) -> COL | K6: Picked | L6: =VLOOKUP($B6,PickedPlayers!D:Q,9,FALSE) -> 0 | M6: =VLOOKUP($C6,Fixtures!A:I,5,FALSE) -> CRO | N6: Picked | O6: =VLOOKUP($B6,PickedPlayers!D:Q,10,FALSE) -> 0 | P6: =VLOOKUP($C6,Fixtures!A:I,6,FALSE) -> SPA | R6: =VLOOKUP($B6,PickedPlayers!D:Q,11,FALSE) -> 0 | S6: =VLOOKUP($C6,Fixtures!A:I,7,FALSE) -> TBC | U6: =VLOOKUP($B6,PickedPlayers!D:Q,12,FALSE) -> 0 | V6: =VLOOKUP($C6,Fixtures!A:I,8,FALSE) -> TBC | X6: =VLOOKUP($B6,PickedPlayers!D:Q,13,FALSE) -> 0 | Y6: =VLOOKUP($C6,Fixtures!A:I,9,FALSE) -> TBC | AA6: =VLOOKUP($B6,PickedPlayers!D:Q,14,FALSE) -> 0
A7: DEF | B7: Alejandro Grimaldo | C7: Spain | D7: =VLOOKUP($C7,Fixtures!A:I,2,FALSE) -> CAP | E7: Subbed Off | F7: =VLOOKUP($B7,PickedPlayers!D:Q,7,FALSE) -> 0 | G7: =VLOOKUP($C7,Fixtures!A:I,3,FALSE) -> SAU | H7: Sub 2 | I7: =VLOOKUP($B7,PickedPlayers!D:Q,8,FALSE) -> 0 | J7: =VLOOKUP($C7,Fixtures!A:I,4,FALSE) -> URU | K7: Sub 2 | L7: =VLOOKUP($B7,PickedPlayers!D:Q,9,FALSE) -> 0 | M7: =VLOOKUP($C7,Fixtures!A:I,5,FALSE) -> AUS | N7: Picked | O7: =VLOOKUP($B7,PickedPlayers!D:Q,10,FALSE) -> 0 | P7: =VLOOKUP($C7,Fixtures!A:I,6,FALSE) -> POR | R7: =VLOOKUP($B7,PickedPlayers!D:Q,11,FALSE) -> 0 | S7: =VLOOKUP($C7,Fixtures!A:I,7,FALSE) -> TBC | U7: =VLOOKUP($B7,PickedPlayers!D:Q,12,FALSE) -> 0 | V7: =VLOOKUP($C7,Fixtures!A:I,8,FALSE) -> TBC | X7: =VLOOKUP($B7,PickedPlayers!D:Q,13,FALSE) -> 0 | Y7: =VLOOKUP($C7,Fixtures!A:I,9,FALSE) -> TBC | AA7: =VLOOKUP($B7,PickedPlayers!D:Q,14,FALSE) -> 0
A8: DEF | B8: A. Rüdiger | C8: Germany | D8: =VLOOKUP($C8,Fixtures!A:I,2,FALSE) -> CUR | E8: Picked | F8: =VLOOKUP($B8,PickedPlayers!D:Q,7,FALSE) -> 0 | G8: =VLOOKUP($C8,Fixtures!A:I,3,FALSE) -> IVO | H8: Picked | I8: =VLOOKUP($B8,PickedPlayers!D:Q,8,FALSE) -> 0 | J8: =VLOOKUP($C8,Fixtures!A:I,4,FALSE) -> ECU | K8: Picked | L8: =VLOOKUP($B8,PickedPlayers!D:Q,9,FALSE) -> 0 | M8: =VLOOKUP($C8,Fixtures!A:I,5,FALSE) -> PAR | N8: Sub 2 | O8: =VLOOKUP($B8,PickedPlayers!D:Q,10,FALSE) -> 0 | P8: =VLOOKUP($C8,Fixtures!A:I,6,FALSE) -> out | R8: =VLOOKUP($B8,PickedPlayers!D:Q,11,FALSE) -> 0 | S8: =VLOOKUP($C8,Fixtures!A:I,7,FALSE) -> out | U8: =VLOOKUP($B8,PickedPlayers!D:Q,12,FALSE) -> 0 | V8: =VLOOKUP($C8,Fixtures!A:I,8,FALSE) -> out | X8: =VLOOKUP($B8,PickedPlayers!D:Q,13,FALSE) -> 0 | Y8: =VLOOKUP($C8,Fixtures!A:I,9,FALSE) -> out | AA8: =VLOOKUP($B8,PickedPlayers!D:Q,14,FALSE) -> 0
A9: DEF | B9: J. Stones | C9: England | D9: =VLOOKUP($C9,Fixtures!A:I,2,FALSE) -> CRO | E9: Sub 4 | F9: =VLOOKUP($B9,PickedPlayers!D:Q,7,FALSE) -> 0 | G9: =VLOOKUP($C9,Fixtures!A:I,3,FALSE) -> GHA | H9: Sub 4 | I9: =VLOOKUP($B9,PickedPlayers!D:Q,8,FALSE) -> 0 | J9: =VLOOKUP($C9,Fixtures!A:I,4,FALSE) -> PAN | K9: Sub 4 | L9: =VLOOKUP($B9,PickedPlayers!D:Q,9,FALSE) -> 0 | M9: =VLOOKUP($C9,Fixtures!A:I,5,FALSE) -> CON | N9: Sub 3 | O9: =VLOOKUP($B9,PickedPlayers!D:Q,10,FALSE) -> 0 | P9: =VLOOKUP($C9,Fixtures!A:I,6,FALSE) -> MEX | R9: =VLOOKUP($B9,PickedPlayers!D:Q,11,FALSE) -> 0 | S9: =VLOOKUP($C9,Fixtures!A:I,7,FALSE) -> TBC | U9: =VLOOKUP($B9,PickedPlayers!D:Q,12,FALSE) -> 0 | V9: =VLOOKUP($C9,Fixtures!A:I,8,FALSE) -> TBC | X9: =VLOOKUP($B9,PickedPlayers!D:Q,13,FALSE) -> 0 | Y9: =VLOOKUP($C9,Fixtures!A:I,9,FALSE) -> TBC | AA9: =VLOOKUP($B9,PickedPlayers!D:Q,14,FALSE) -> 0
A10: MID | B10: J. Bellingham | C10: England | D10: =VLOOKUP($C10,Fixtures!A:I,2,FALSE) -> CRO | E10: Picked | F10: =VLOOKUP($B10,PickedPlayers!D:Q,7,FALSE) -> 0 | G10: =VLOOKUP($C10,Fixtures!A:I,3,FALSE) -> GHA | H10: Vice Captain | I10: =VLOOKUP($B10,PickedPlayers!D:Q,8,FALSE) -> 0 | J10: =VLOOKUP($C10,Fixtures!A:I,4,FALSE) -> PAN | K10: Vice Captain | L10: =VLOOKUP($B10,PickedPlayers!D:Q,9,FALSE) -> 0 | M10: =VLOOKUP($C10,Fixtures!A:I,5,FALSE) -> CON | N10: Captain | O10: =VLOOKUP($B10,PickedPlayers!D:Q,10,FALSE) -> 0 | P10: =VLOOKUP($C10,Fixtures!A:I,6,FALSE) -> MEX | R10: =VLOOKUP($B10,PickedPlayers!D:Q,11,FALSE) -> 0 | S10: =VLOOKUP($C10,Fixtures!A:I,7,FALSE) -> TBC | U10: =VLOOKUP($B10,PickedPlayers!D:Q,12,FALSE) -> 0 | V10: =VLOOKUP($C10,Fixtures!A:I,8,FALSE) -> TBC | X10: =VLOOKUP($B10,PickedPlayers!D:Q,13,FALSE) -> 0 | Y10: =VLOOKUP($C10,Fixtures!A:I,9,FALSE) -> TBC | AA10: =VLOOKUP($B10,PickedPlayers!D:Q,14,FALSE) -> 0
A11: MID | B11: K. De Bruyne | C11: Belgium | D11: =VLOOKUP($C11,Fixtures!A:I,2,FALSE) -> EGY | E11: Captain | F11: =VLOOKUP($B11,PickedPlayers!D:Q,7,FALSE) -> 0 | G11: =VLOOKUP($C11,Fixtures!A:I,3,FALSE) -> IRA | H11: Picked | I11: =VLOOKUP($B11,PickedPlayers!D:Q,8,FALSE) -> 0 | J11: =VLOOKUP($C11,Fixtures!A:I,4,FALSE) -> NZL | K11: Picked | L11: =VLOOKUP($B11,PickedPlayers!D:Q,9,FALSE) -> 0 | M11: =VLOOKUP($C11,Fixtures!A:I,5,FALSE) -> SEN | N11: Picked | O11: =VLOOKUP($B11,PickedPlayers!D:Q,10,FALSE) -> 0 | P11: =VLOOKUP($C11,Fixtures!A:I,6,FALSE) -> USA | R11: =VLOOKUP($B11,PickedPlayers!D:Q,11,FALSE) -> 0 | S11: =VLOOKUP($C11,Fixtures!A:I,7,FALSE) -> TBC | U11: =VLOOKUP($B11,PickedPlayers!D:Q,12,FALSE) -> 0 | V11: =VLOOKUP($C11,Fixtures!A:I,8,FALSE) -> TBC | X11: =VLOOKUP($B11,PickedPlayers!D:Q,13,FALSE) -> 0 | Y11: =VLOOKUP($C11,Fixtures!A:I,9,FALSE) -> TBC | AA11: =VLOOKUP($B11,PickedPlayers!D:Q,14,FALSE) -> 0
A12: MID | B12: F. Valverde | C12: Uruguay | D12: =VLOOKUP($C12,Fixtures!A:I,2,FALSE) -> SAU | E12: Picked | F12: =VLOOKUP($B12,PickedPlayers!D:Q,7,FALSE) -> 0 | G12: =VLOOKUP($C12,Fixtures!A:I,3,FALSE) -> CAP | H12: Picked | I12: =VLOOKUP($B12,PickedPlayers!D:Q,8,FALSE) -> 0 | J12: =VLOOKUP($C12,Fixtures!A:I,4,FALSE) -> SPA | K12: Picked | L12: =VLOOKUP($B12,PickedPlayers!D:Q,9,FALSE) -> 0 | M12: CUT | P12: CUT | S12: CUT | V12: CUT | Y12: CUT
A13: MID | B13: Dani Olmo | C13: Spain | D13: =VLOOKUP($C13,Fixtures!A:I,2,FALSE) -> CAP | E13: Picked | F13: =VLOOKUP($B13,PickedPlayers!D:Q,7,FALSE) -> 0 | G13: =VLOOKUP($C13,Fixtures!A:I,3,FALSE) -> SAU | H13: Picked | I13: =VLOOKUP($B13,PickedPlayers!D:Q,8,FALSE) -> 0 | J13: =VLOOKUP($C13,Fixtures!A:I,4,FALSE) -> URU | K13: Picked | L13: =VLOOKUP($B13,PickedPlayers!D:Q,9,FALSE) -> 0 | M13: =VLOOKUP($C13,Fixtures!A:I,5,FALSE) -> AUS | N13: Picked | O13: =VLOOKUP($B13,PickedPlayers!D:Q,10,FALSE) -> 0 | P13: =VLOOKUP($C13,Fixtures!A:I,6,FALSE) -> POR | R13: =VLOOKUP($B13,PickedPlayers!D:Q,11,FALSE) -> 0 | S13: =VLOOKUP($C13,Fixtures!A:I,7,FALSE) -> TBC | U13: =VLOOKUP($B13,PickedPlayers!D:Q,12,FALSE) -> 0 | V13: =VLOOKUP($C13,Fixtures!A:I,8,FALSE) -> TBC | X13: =VLOOKUP($B13,PickedPlayers!D:Q,13,FALSE) -> 0 | Y13: =VLOOKUP($C13,Fixtures!A:I,9,FALSE) -> TBC | AA13: =VLOOKUP($B13,PickedPlayers!D:Q,14,FALSE) -> 0
A14: MID | B14: F. Nmecha | C14: Germany | D14: GER | M14: =VLOOKUP($C14,Fixtures!A:I,5,FALSE) -> PAR | N14: Picked | O14: =VLOOKUP($B14,PickedPlayers!D:Q,10,FALSE) -> 0 | P14: =VLOOKUP($C14,Fixtures!A:I,6,FALSE) -> out | R14: =VLOOKUP($B14,PickedPlayers!D:Q,11,FALSE) -> 0 | S14: =VLOOKUP($C14,Fixtures!A:I,7,FALSE) -> out | U14: =VLOOKUP($B14,PickedPlayers!D:Q,12,FALSE) -> 0 | V14: =VLOOKUP($C14,Fixtures!A:I,8,FALSE) -> out | X14: =VLOOKUP($B14,PickedPlayers!D:Q,13,FALSE) -> 0 | Y14: =VLOOKUP($C14,Fixtures!A:I,9,FALSE) -> out | AA14: =VLOOKUP($B14,PickedPlayers!D:Q,14,FALSE) -> 0
A15: FWD | B15: K. Mbappé | C15: France | D15: =VLOOKUP($C15,Fixtures!A:I,2,FALSE) -> SEN | E15: Vice Captain | F15: =VLOOKUP($B15,PickedPlayers!D:Q,7,FALSE) -> 0 | G15: =VLOOKUP($C15,Fixtures!A:I,3,FALSE) -> IRQ | H15: Captain | I15: =VLOOKUP($B15,PickedPlayers!D:Q,8,FALSE) -> 0 | J15: =VLOOKUP($C15,Fixtures!A:I,4,FALSE) -> NOR | K15: Captain | L15: =VLOOKUP($B15,PickedPlayers!D:Q,9,FALSE) -> 0 | M15: =VLOOKUP($C15,Fixtures!A:I,5,FALSE) -> SWE | N15: Vice Captain | O15: =VLOOKUP($B15,PickedPlayers!D:Q,10,FALSE) -> 0 | P15: =VLOOKUP($C15,Fixtures!A:I,6,FALSE) -> PAR | R15: =VLOOKUP($B15,PickedPlayers!D:Q,11,FALSE) -> 0 | S15: =VLOOKUP($C15,Fixtures!A:I,7,FALSE) -> TBC | U15: =VLOOKUP($B15,PickedPlayers!D:Q,12,FALSE) -> 0 | V15: =VLOOKUP($C15,Fixtures!A:I,8,FALSE) -> TBC | X15: =VLOOKUP($B15,PickedPlayers!D:Q,13,FALSE) -> 0 | Y15: =VLOOKUP($C15,Fixtures!A:I,9,FALSE) -> TBC | AA15: =VLOOKUP($B15,PickedPlayers!D:Q,14,FALSE) -> 0
A16: FWD | B16: Lautaro Martínez | C16: Argentina | D16: =VLOOKUP($C16,Fixtures!A:I,2,FALSE) -> ALG | E16: Picked | F16: =VLOOKUP($B16,PickedPlayers!D:Q,7,FALSE) -> 0 | G16: =VLOOKUP($C16,Fixtures!A:I,3,FALSE) -> AUT | H16: Sub 2 | I16: =VLOOKUP($B16,PickedPlayers!D:Q,8,FALSE) -> 0 | J16: =VLOOKUP($C16,Fixtures!A:I,4,FALSE) -> JOR | K16: Sub 2 | L16: =VLOOKUP($B16,PickedPlayers!D:Q,9,FALSE) -> 0 | M16: =VLOOKUP($C16,Fixtures!A:I,5,FALSE) -> CAP | N16: Picked | O16: =VLOOKUP($B16,PickedPlayers!D:Q,10,FALSE) -> 0 | P16: =VLOOKUP($C16,Fixtures!A:I,6,FALSE) -> TBC | R16: =VLOOKUP($B16,PickedPlayers!D:Q,11,FALSE) -> 0 | S16: =VLOOKUP($C16,Fixtures!A:I,7,FALSE) -> TBC | U16: =VLOOKUP($B16,PickedPlayers!D:Q,12,FALSE) -> 0 | V16: =VLOOKUP($C16,Fixtures!A:I,8,FALSE) -> TBC | X16: =VLOOKUP($B16,PickedPlayers!D:Q,13,FALSE) -> 0 | Y16: =VLOOKUP($C16,Fixtures!A:I,9,FALSE) -> TBC | AA16: =VLOOKUP($B16,PickedPlayers!D:Q,14,FALSE) -> 0
A17: FWD | B17: D. Núñez | C17: Uruguay | D17: =VLOOKUP($C17,Fixtures!A:I,2,FALSE) -> SAU | E17: Picked | F17: =VLOOKUP($B17,PickedPlayers!D:Q,7,FALSE) -> 0 | G17: =VLOOKUP($C17,Fixtures!A:I,3,FALSE) -> CAP | H17: Sub 1 | I17: =VLOOKUP($B17,PickedPlayers!D:Q,8,FALSE) -> 0 | J17: =VLOOKUP($C17,Fixtures!A:I,4,FALSE) -> SPA | K17: Sub 1 | L17: =VLOOKUP($B17,PickedPlayers!D:Q,9,FALSE) -> 0 | M17: =VLOOKUP($C17,Fixtures!A:I,5,FALSE) -> out | O17: =VLOOKUP($B17,PickedPlayers!D:Q,10,FALSE) -> 0 | P17: =VLOOKUP($C17,Fixtures!A:I,6,FALSE) -> out | R17: =VLOOKUP($B17,PickedPlayers!D:Q,11,FALSE) -> 0 | S17: =VLOOKUP($C17,Fixtures!A:I,7,FALSE) -> out | U17: =VLOOKUP($B17,PickedPlayers!D:Q,12,FALSE) -> 0 | V17: =VLOOKUP($C17,Fixtures!A:I,8,FALSE) -> out | X17: =VLOOKUP($B17,PickedPlayers!D:Q,13,FALSE) -> 0 | Y17: =VLOOKUP($C17,Fixtures!A:I,9,FALSE) -> out | AA17: =VLOOKUP($B17,PickedPlayers!D:Q,14,FALSE) -> 0
A18: FWD | B18: L. Trossard | C18: Belgium | D18: =VLOOKUP($C18,Fixtures!A:I,2,FALSE) -> EGY | E18: Sub 1 | F18: =VLOOKUP($B18,PickedPlayers!D:Q,7,FALSE) -> 0 | G18: =VLOOKUP($C18,Fixtures!A:I,3,FALSE) -> IRA | H18: Picked | I18: =VLOOKUP($B18,PickedPlayers!D:Q,8,FALSE) -> 0 | J18: =VLOOKUP($C18,Fixtures!A:I,4,FALSE) -> NZL | K18: Picked | L18: =VLOOKUP($B18,PickedPlayers!D:Q,9,FALSE) -> 0 | M18: =VLOOKUP($C18,Fixtures!A:I,5,FALSE) -> SEN | N18: Picked | O18: =VLOOKUP($B18,PickedPlayers!D:Q,10,FALSE) -> 0 | P18: =VLOOKUP($C18,Fixtures!A:I,6,FALSE) -> USA | R18: =VLOOKUP($B18,PickedPlayers!D:Q,11,FALSE) -> 0 | S18: =VLOOKUP($C18,Fixtures!A:I,7,FALSE) -> TBC | U18: =VLOOKUP($B18,PickedPlayers!D:Q,12,FALSE) -> 0 | V18: =VLOOKUP($C18,Fixtures!A:I,8,FALSE) -> TBC | X18: =VLOOKUP($B18,PickedPlayers!D:Q,13,FALSE) -> 0 | Y18: =VLOOKUP($C18,Fixtures!A:I,9,FALSE) -> TBC | AA18: =VLOOKUP($B18,PickedPlayers!D:Q,14,FALSE) -> 0
A19: FWD | B19: B. Barcola | C19: France | D19: =VLOOKUP($C19,Fixtures!A:I,2,FALSE) -> SEN | E19: Sub 2 | F19: =VLOOKUP($B19,PickedPlayers!D:Q,7,FALSE) -> 0 | G19: =VLOOKUP($C19,Fixtures!A:I,3,FALSE) -> IRQ | H19: Picked | I19: =VLOOKUP($B19,PickedPlayers!D:Q,8,FALSE) -> 0 | J19: =VLOOKUP($C19,Fixtures!A:I,4,FALSE) -> NOR | K19: Picked | L19: =VLOOKUP($B19,PickedPlayers!D:Q,9,FALSE) -> 0 | M19: =VLOOKUP($C19,Fixtures!A:I,5,FALSE) -> SWE | N19: Sub 1 | O19: =VLOOKUP($B19,PickedPlayers!D:Q,10,FALSE) -> 0 | P19: =VLOOKUP($C19,Fixtures!A:I,6,FALSE) -> PAR | R19: =VLOOKUP($B19,PickedPlayers!D:Q,11,FALSE) -> 0 | S19: =VLOOKUP($C19,Fixtures!A:I,7,FALSE) -> TBC | U19: =VLOOKUP($B19,PickedPlayers!D:Q,12,FALSE) -> 0 | V19: =VLOOKUP($C19,Fixtures!A:I,8,FALSE) -> TBC | X19: =VLOOKUP($B19,PickedPlayers!D:Q,13,FALSE) -> 0 | Y19: =VLOOKUP($C19,Fixtures!A:I,9,FALSE) -> TBC | AA19: =VLOOKUP($B19,PickedPlayers!D:Q,14,FALSE) -> 0

Sheet Taylor
A1: 1 Captain 1 Sub | D1: Group (1) | G1: Group (2) | J1: Group (3) | M1: Last 32 | P1: Last 16 | S1: Quarter Final | V1: Semi Final | Y1: 3rd Place / Final
A2: Position | B2: Player | C2: Nationality | D2: Opposition | E2: Selection | F2: Points | G2: Opposition | H2: Selection | I2: Points | J2: Opposition | K2: Selection | L2: Points | M2: Opposition | N2: Selection | O2: Points | P2: Opposition | Q2: Selection | R2: Points | S2: Opposition | T2: Selection | U2: Points | V2: Opposition | W2: Selection | X2: Points | Y2: Opposition | Z2: Selection | AA2: Points
A3: GK | B3: J. Pickford | C3: England | D3: =VLOOKUP($C3,Fixtures!A:I,2,FALSE) -> CRO | E3: Picked | F3: =VLOOKUP($B3,PickedPlayers!D:Q,7,FALSE) -> 0 | G3: =VLOOKUP($C3,Fixtures!A:I,3,FALSE) -> GHA | H3: Picked | I3: =VLOOKUP($B3,PickedPlayers!D:Q,8,FALSE) -> 0 | J3: =VLOOKUP($C3,Fixtures!A:I,4,FALSE) -> PAN | K3: Picked | L3: =VLOOKUP($B3,PickedPlayers!D:Q,9,FALSE) -> 0 | M3: =VLOOKUP($C3,Fixtures!A:I,5,FALSE) -> CON | N3: Picked | O3: =VLOOKUP($B3,PickedPlayers!D:Q,10,FALSE) -> 0 | P3: =VLOOKUP($C3,Fixtures!A:I,6,FALSE) -> MEX | Q3: Picked | R3: =VLOOKUP($B3,PickedPlayers!D:Q,11,FALSE) -> 0 | S3: =VLOOKUP($C3,Fixtures!A:I,7,FALSE) -> TBC | U3: =VLOOKUP($B3,PickedPlayers!D:Q,12,FALSE) -> 0 | V3: =VLOOKUP($C3,Fixtures!A:I,8,FALSE) -> TBC | X3: =VLOOKUP($B3,PickedPlayers!D:Q,13,FALSE) -> 0 | Y3: =VLOOKUP($C3,Fixtures!A:I,9,FALSE) -> TBC | AA3: =VLOOKUP($B3,PickedPlayers!D:Q,14,FALSE) -> 0
A4: GK | B4: Z. Suzuki | C4: Japan | D4: =VLOOKUP($C4,Fixtures!A:I,2,FALSE) -> NED | E4: Sub GK | F4: =VLOOKUP($B4,PickedPlayers!D:Q,7,FALSE) -> 0 | G4: =VLOOKUP($C4,Fixtures!A:I,3,FALSE) -> TUN | H4: Sub GK | I4: =VLOOKUP($B4,PickedPlayers!D:Q,8,FALSE) -> 0 | J4: =VLOOKUP($C4,Fixtures!A:I,4,FALSE) -> SWE | K4: Sub GK | L4: =VLOOKUP($B4,PickedPlayers!D:Q,9,FALSE) -> 0 | M4: =VLOOKUP($C4,Fixtures!A:I,5,FALSE) -> BRA | N4: Sub GK | O4: =VLOOKUP($B4,PickedPlayers!D:Q,10,FALSE) -> 0 | P4: =VLOOKUP($C4,Fixtures!A:I,6,FALSE) -> out | R4: =VLOOKUP($B4,PickedPlayers!D:Q,11,FALSE) -> 0 | S4: =VLOOKUP($C4,Fixtures!A:I,7,FALSE) -> out | U4: =VLOOKUP($B4,PickedPlayers!D:Q,12,FALSE) -> 0 | V4: =VLOOKUP($C4,Fixtures!A:I,8,FALSE) -> out | X4: =VLOOKUP($B4,PickedPlayers!D:Q,13,FALSE) -> 0 | Y4: =VLOOKUP($C4,Fixtures!A:I,9,FALSE) -> out | AA4: =VLOOKUP($B4,PickedPlayers!D:Q,14,FALSE) -> 0
A5: DEF | B5: W. Saliba | C5: France | D5: =VLOOKUP($C5,Fixtures!A:I,2,FALSE) -> SEN | E5: Picked | F5: =VLOOKUP($B5,PickedPlayers!D:Q,7,FALSE) -> 0 | G5: =VLOOKUP($C5,Fixtures!A:I,3,FALSE) -> IRQ | H5: Picked | I5: =VLOOKUP($B5,PickedPlayers!D:Q,8,FALSE) -> 0 | J5: =VLOOKUP($C5,Fixtures!A:I,4,FALSE) -> NOR | K5: Sub 3 | L5: =VLOOKUP($B5,PickedPlayers!D:Q,9,FALSE) -> 0 | M5: =VLOOKUP($C5,Fixtures!A:I,5,FALSE) -> SWE | N5: Picked | O5: =VLOOKUP($B5,PickedPlayers!D:Q,10,FALSE) -> 0 | P5: =VLOOKUP($C5,Fixtures!A:I,6,FALSE) -> PAR | Q5: Picked | R5: =VLOOKUP($B5,PickedPlayers!D:Q,11,FALSE) -> 0 | S5: =VLOOKUP($C5,Fixtures!A:I,7,FALSE) -> TBC | U5: =VLOOKUP($B5,PickedPlayers!D:Q,12,FALSE) -> 0 | V5: =VLOOKUP($C5,Fixtures!A:I,8,FALSE) -> TBC | X5: =VLOOKUP($B5,PickedPlayers!D:Q,13,FALSE) -> 0 | Y5: =VLOOKUP($C5,Fixtures!A:I,9,FALSE) -> TBC | AA5: =VLOOKUP($B5,PickedPlayers!D:Q,14,FALSE) -> 0
A6: DEF | B6: A. Robinson | C6: USA | D6: =VLOOKUP($C6,Fixtures!A:I,2,FALSE) -> PAR | E6: Sub 3 | F6: =VLOOKUP($B6,PickedPlayers!D:Q,7,FALSE) -> 0 | G6: =VLOOKUP($C6,Fixtures!A:I,3,FALSE) -> AUS | H6: Picked | I6: =VLOOKUP($B6,PickedPlayers!D:Q,8,FALSE) -> 0 | J6: =VLOOKUP($C6,Fixtures!A:I,4,FALSE) -> TUR | K6: Picked | L6: =VLOOKUP($B6,PickedPlayers!D:Q,9,FALSE) -> 0 | M6: =VLOOKUP($C6,Fixtures!A:I,5,FALSE) -> BOS | N6: Vice Captain | O6: =VLOOKUP($B6,PickedPlayers!D:Q,10,FALSE) -> 0 | P6: =VLOOKUP($C6,Fixtures!A:I,6,FALSE) -> BEL | Q6: Picked | R6: =VLOOKUP($B6,PickedPlayers!D:Q,11,FALSE) -> 0 | S6: =VLOOKUP($C6,Fixtures!A:I,7,FALSE) -> TBC | U6: =VLOOKUP($B6,PickedPlayers!D:Q,12,FALSE) -> 0 | V6: =VLOOKUP($C6,Fixtures!A:I,8,FALSE) -> TBC | X6: =VLOOKUP($B6,PickedPlayers!D:Q,13,FALSE) -> 0 | Y6: =VLOOKUP($C6,Fixtures!A:I,9,FALSE) -> TBC | AA6: =VLOOKUP($B6,PickedPlayers!D:Q,14,FALSE) -> 0
A7: DEF | B7: L. Vušković | C7: Croatia | D7: =VLOOKUP($C7,Fixtures!A:I,2,FALSE) -> ENG | E7: Sub 4 | F7: =VLOOKUP($B7,PickedPlayers!D:Q,7,FALSE) -> 0 | G7: =VLOOKUP($C7,Fixtures!A:I,3,FALSE) -> PAN | H7: Subbed Off | I7: =VLOOKUP($B7,PickedPlayers!D:Q,8,FALSE) -> 0 | J7: =VLOOKUP($C7,Fixtures!A:I,4,FALSE) -> GHA | K7: Subbed Off | L7: =VLOOKUP($B7,PickedPlayers!D:Q,9,FALSE) -> 0 | M7: =VLOOKUP($C7,Fixtures!A:I,5,FALSE) -> POR | N7: Sub 2 | O7: =VLOOKUP($B7,PickedPlayers!D:Q,10,FALSE) -> 0 | P7: =VLOOKUP($C7,Fixtures!A:I,6,FALSE) -> out | R7: =VLOOKUP($B7,PickedPlayers!D:Q,11,FALSE) -> 0 | S7: =VLOOKUP($C7,Fixtures!A:I,7,FALSE) -> out | U7: =VLOOKUP($B7,PickedPlayers!D:Q,12,FALSE) -> 0 | V7: =VLOOKUP($C7,Fixtures!A:I,8,FALSE) -> out | X7: =VLOOKUP($B7,PickedPlayers!D:Q,13,FALSE) -> 0 | Y7: =VLOOKUP($C7,Fixtures!A:I,9,FALSE) -> out | AA7: =VLOOKUP($B7,PickedPlayers!D:Q,14,FALSE) -> 0
A8: DEF | B8: Lisandro Martínez | C8: Argentina | D8: =VLOOKUP($C8,Fixtures!A:I,2,FALSE) -> ALG | E8: Picked | F8: =VLOOKUP($B8,PickedPlayers!D:Q,7,FALSE) -> 0 | G8: =VLOOKUP($C8,Fixtures!A:I,3,FALSE) -> AUT | H8: Picked | I8: =VLOOKUP($B8,PickedPlayers!D:Q,8,FALSE) -> 0 | J8: =VLOOKUP($C8,Fixtures!A:I,4,FALSE) -> JOR | K8: Vice Captain | L8: =VLOOKUP($B8,PickedPlayers!D:Q,9,FALSE) -> 0 | M8: =VLOOKUP($C8,Fixtures!A:I,5,FALSE) -> CAP | N8: Picked | O8: =VLOOKUP($B8,PickedPlayers!D:Q,10,FALSE) -> 0 | P8: =VLOOKUP($C8,Fixtures!A:I,6,FALSE) -> TBC | R8: =VLOOKUP($B8,PickedPlayers!D:Q,11,FALSE) -> 0 | S8: =VLOOKUP($C8,Fixtures!A:I,7,FALSE) -> TBC | U8: =VLOOKUP($B8,PickedPlayers!D:Q,12,FALSE) -> 0 | V8: =VLOOKUP($C8,Fixtures!A:I,8,FALSE) -> TBC | X8: =VLOOKUP($B8,PickedPlayers!D:Q,13,FALSE) -> 0 | Y8: =VLOOKUP($C8,Fixtures!A:I,9,FALSE) -> TBC | AA8: =VLOOKUP($B8,PickedPlayers!D:Q,14,FALSE) -> 0
A9: DEF | B9: D. Muñoz | C9: Colombia | D9: =VLOOKUP($C9,Fixtures!A:I,2,FALSE) -> UZB | E9: Picked | F9: =VLOOKUP($B9,PickedPlayers!D:Q,7,FALSE) -> 0 | G9: =VLOOKUP($C9,Fixtures!A:I,3,FALSE) -> CON | H9: Picked | I9: =VLOOKUP($B9,PickedPlayers!D:Q,8,FALSE) -> 0 | J9: =VLOOKUP($C9,Fixtures!A:I,4,FALSE) -> POR | K9: Picked | L9: =VLOOKUP($B9,PickedPlayers!D:Q,9,FALSE) -> 0 | M9: =VLOOKUP($C9,Fixtures!A:I,5,FALSE) -> GHA | N9: Picked | O9: =VLOOKUP($B9,PickedPlayers!D:Q,10,FALSE) -> 0 | P9: =VLOOKUP($C9,Fixtures!A:I,6,FALSE) -> TBC | R9: =VLOOKUP($B9,PickedPlayers!D:Q,11,FALSE) -> 0 | S9: =VLOOKUP($C9,Fixtures!A:I,7,FALSE) -> TBC | U9: =VLOOKUP($B9,PickedPlayers!D:Q,12,FALSE) -> 0 | V9: =VLOOKUP($C9,Fixtures!A:I,8,FALSE) -> TBC | X9: =VLOOKUP($B9,PickedPlayers!D:Q,13,FALSE) -> 0 | Y9: =VLOOKUP($C9,Fixtures!A:I,9,FALSE) -> TBC | AA9: =VLOOKUP($B9,PickedPlayers!D:Q,14,FALSE) -> 0
A10: MID | B10: S. McTominay | C10: Scotland | D10: =VLOOKUP($C10,Fixtures!A:I,2,FALSE) -> HAI | E10: Vice Captain | F10: =VLOOKUP($B10,PickedPlayers!D:Q,7,FALSE) -> 0 | G10: =VLOOKUP($C10,Fixtures!A:I,3,FALSE) -> MOR | H10: Picked | I10: =VLOOKUP($B10,PickedPlayers!D:Q,8,FALSE) -> 0 | J10: =VLOOKUP($C10,Fixtures!A:I,4,FALSE) -> BRA | K10: Picked | L10: =VLOOKUP($B10,PickedPlayers!D:Q,9,FALSE) -> 0 | M10: =VLOOKUP($C10,Fixtures!A:I,5,FALSE) -> out | O10: =VLOOKUP($B10,PickedPlayers!D:Q,10,FALSE) -> 0 | P10: =VLOOKUP($C10,Fixtures!A:I,6,FALSE) -> out | R10: =VLOOKUP($B10,PickedPlayers!D:Q,11,FALSE) -> 0 | S10: =VLOOKUP($C10,Fixtures!A:I,7,FALSE) -> out | U10: =VLOOKUP($B10,PickedPlayers!D:Q,12,FALSE) -> 0 | V10: =VLOOKUP($C10,Fixtures!A:I,8,FALSE) -> out | X10: =VLOOKUP($B10,PickedPlayers!D:Q,13,FALSE) -> 0 | Y10: =VLOOKUP($C10,Fixtures!A:I,9,FALSE) -> out | AA10: =VLOOKUP($B10,PickedPlayers!D:Q,14,FALSE) -> 0
A11: MID | B11: C. Pulisic | C11: USA | D11: =VLOOKUP($C11,Fixtures!A:I,2,FALSE) -> PAR | E11: Picked | F11: =VLOOKUP($B11,PickedPlayers!D:Q,7,FALSE) -> 0 | G11: =VLOOKUP($C11,Fixtures!A:I,3,FALSE) -> AUS | H11: Subbed Off | I11: =VLOOKUP($B11,PickedPlayers!D:Q,8,FALSE) -> 0 | J11: =VLOOKUP($C11,Fixtures!A:I,4,FALSE) -> TUR | K11: Picked | L11: =VLOOKUP($B11,PickedPlayers!D:Q,9,FALSE) -> 0 | M11: =VLOOKUP($C11,Fixtures!A:I,5,FALSE) -> BOS | N11: Picked | O11: =VLOOKUP($B11,PickedPlayers!D:Q,10,FALSE) -> 0 | P11: =VLOOKUP($C11,Fixtures!A:I,6,FALSE) -> BEL | Q11: Picked | R11: =VLOOKUP($B11,PickedPlayers!D:Q,11,FALSE) -> 0 | S11: =VLOOKUP($C11,Fixtures!A:I,7,FALSE) -> TBC | U11: =VLOOKUP($B11,PickedPlayers!D:Q,12,FALSE) -> 0 | V11: =VLOOKUP($C11,Fixtures!A:I,8,FALSE) -> TBC | X11: =VLOOKUP($B11,PickedPlayers!D:Q,13,FALSE) -> 0 | Y11: =VLOOKUP($C11,Fixtures!A:I,9,FALSE) -> TBC | AA11: =VLOOKUP($B11,PickedPlayers!D:Q,14,FALSE) -> 0
A12: MID | B12: M. Ødegaard | C12: Norway | D12: =VLOOKUP($C12,Fixtures!A:I,2,FALSE) -> IRQ | E12: Picked | F12: =VLOOKUP($B12,PickedPlayers!D:Q,7,FALSE) -> 0 | G12: =VLOOKUP($C12,Fixtures!A:I,3,FALSE) -> SEN | H12: Picked | I12: =VLOOKUP($B12,PickedPlayers!D:Q,8,FALSE) -> 0 | J12: =VLOOKUP($C12,Fixtures!A:I,4,FALSE) -> FRA | K12: Picked | L12: =VLOOKUP($B12,PickedPlayers!D:Q,9,FALSE) -> 0 | M12: =VLOOKUP($C12,Fixtures!A:I,5,FALSE) -> IVO | N12: Picked | O12: =VLOOKUP($B12,PickedPlayers!D:Q,10,FALSE) -> 0 | P12: =VLOOKUP($C12,Fixtures!A:I,6,FALSE) -> BRA | Q12: Picked | R12: =VLOOKUP($B12,PickedPlayers!D:Q,11,FALSE) -> 0 | S12: =VLOOKUP($C12,Fixtures!A:I,7,FALSE) -> TBC | U12: =VLOOKUP($B12,PickedPlayers!D:Q,12,FALSE) -> 0 | V12: =VLOOKUP($C12,Fixtures!A:I,8,FALSE) -> TBC | X12: =VLOOKUP($B12,PickedPlayers!D:Q,13,FALSE) -> 0 | Y12: =VLOOKUP($C12,Fixtures!A:I,9,FALSE) -> TBC | AA12: =VLOOKUP($B12,PickedPlayers!D:Q,14,FALSE) -> 0
A13: MID | B13: A. Güler | C13: Turkey | D13: =VLOOKUP($C13,Fixtures!A:I,2,FALSE) -> AUS | E13: Picked | F13: =VLOOKUP($B13,PickedPlayers!D:Q,7,FALSE) -> 0 | G13: =VLOOKUP($C13,Fixtures!A:I,3,FALSE) -> PAR | H13: Picked | I13: =VLOOKUP($B13,PickedPlayers!D:Q,8,FALSE) -> 0 | J13: =VLOOKUP($C13,Fixtures!A:I,4,FALSE) -> USA | K13: Picked | L13: =VLOOKUP($B13,PickedPlayers!D:Q,9,FALSE) -> 0 | M13: CUT | P13: CUT | S13: CUT | V13: CUT | Y13: CUT
A14: MID | B14: J. Manzambi | C14: Switzerland | M14: =VLOOKUP($C14,Fixtures!A:I,5,FALSE) -> ALG | N14: Picked | O14: =VLOOKUP($B14,PickedPlayers!D:Q,10,FALSE) -> 0 | P14: =VLOOKUP($C14,Fixtures!A:I,6,FALSE) -> TBC | Q14: Picked | R14: =VLOOKUP($B14,PickedPlayers!D:Q,11,FALSE) -> 0 | S14: =VLOOKUP($C14,Fixtures!A:I,7,FALSE) -> TBC | U14: =VLOOKUP($B14,PickedPlayers!D:Q,12,FALSE) -> 0 | V14: =VLOOKUP($C14,Fixtures!A:I,8,FALSE) -> TBC | X14: =VLOOKUP($B14,PickedPlayers!D:Q,13,FALSE) -> 0 | Y14: =VLOOKUP($C14,Fixtures!A:I,9,FALSE) -> TBC | AA14: =VLOOKUP($B14,PickedPlayers!D:Q,14,FALSE) -> 0
A15: FWD | B15: H. Kane | C15: England | D15: =VLOOKUP($C15,Fixtures!A:I,2,FALSE) -> CRO | E15: Captain | F15: =VLOOKUP($B15,PickedPlayers!D:Q,7,FALSE) -> 0 | G15: =VLOOKUP($C15,Fixtures!A:I,3,FALSE) -> GHA | H15: Captain | I15: =VLOOKUP($B15,PickedPlayers!D:Q,8,FALSE) -> 0 | J15: =VLOOKUP($C15,Fixtures!A:I,4,FALSE) -> PAN | K15: Picked | L15: =VLOOKUP($B15,PickedPlayers!D:Q,9,FALSE) -> 0 | M15: =VLOOKUP($C15,Fixtures!A:I,5,FALSE) -> CON | N15: Captain | O15: =VLOOKUP($B15,PickedPlayers!D:Q,10,FALSE) -> 0 | P15: =VLOOKUP($C15,Fixtures!A:I,6,FALSE) -> MEX | Q15: Picked | R15: =VLOOKUP($B15,PickedPlayers!D:Q,11,FALSE) -> 0 | S15: =VLOOKUP($C15,Fixtures!A:I,7,FALSE) -> TBC | U15: =VLOOKUP($B15,PickedPlayers!D:Q,12,FALSE) -> 0 | V15: =VLOOKUP($C15,Fixtures!A:I,8,FALSE) -> TBC | X15: =VLOOKUP($B15,PickedPlayers!D:Q,13,FALSE) -> 0 | Y15: =VLOOKUP($C15,Fixtures!A:I,9,FALSE) -> TBC | AA15: =VLOOKUP($B15,PickedPlayers!D:Q,14,FALSE) -> 0
A16: FWD | B16: J. Doku | C16: Belgium | D16: =VLOOKUP($C16,Fixtures!A:I,2,FALSE) -> EGY | E16: Picked | F16: =VLOOKUP($B16,PickedPlayers!D:Q,7,FALSE) -> 0 | G16: =VLOOKUP($C16,Fixtures!A:I,3,FALSE) -> IRA | H16: Sub 2 | I16: =VLOOKUP($B16,PickedPlayers!D:Q,8,FALSE) -> 0 | J16: =VLOOKUP($C16,Fixtures!A:I,4,FALSE) -> NZL | K16: Sub 2 | L16: =VLOOKUP($B16,PickedPlayers!D:Q,9,FALSE) -> 0 | M16: =VLOOKUP($C16,Fixtures!A:I,5,FALSE) -> SEN | N16: Sub 1 | O16: =VLOOKUP($B16,PickedPlayers!D:Q,10,FALSE) -> 0 | P16: =VLOOKUP($C16,Fixtures!A:I,6,FALSE) -> USA | R16: =VLOOKUP($B16,PickedPlayers!D:Q,11,FALSE) -> 0 | S16: =VLOOKUP($C16,Fixtures!A:I,7,FALSE) -> TBC | U16: =VLOOKUP($B16,PickedPlayers!D:Q,12,FALSE) -> 0 | V16: =VLOOKUP($C16,Fixtures!A:I,8,FALSE) -> TBC | X16: =VLOOKUP($B16,PickedPlayers!D:Q,13,FALSE) -> 0 | Y16: =VLOOKUP($C16,Fixtures!A:I,9,FALSE) -> TBC | AA16: =VLOOKUP($B16,PickedPlayers!D:Q,14,FALSE) -> 0
A17: FWD | B17: Nico Williams | C17: Spain | D17: =VLOOKUP($C17,Fixtures!A:I,2,FALSE) -> CAP | E17: Picked | F17: =VLOOKUP($B17,PickedPlayers!D:Q,7,FALSE) -> 0 | G17: =VLOOKUP($C17,Fixtures!A:I,3,FALSE) -> SAU | H17: Picked | I17: =VLOOKUP($B17,PickedPlayers!D:Q,8,FALSE) -> 0 | J17: =VLOOKUP($C17,Fixtures!A:I,4,FALSE) -> URU | K17: Sub 1 | L17: =VLOOKUP($B17,PickedPlayers!D:Q,9,FALSE) -> 0 | M17: =VLOOKUP($C17,Fixtures!A:I,5,FALSE) -> AUS | N17: Sub 3 | O17: =VLOOKUP($B17,PickedPlayers!D:Q,10,FALSE) -> 0 | P17: =VLOOKUP($C17,Fixtures!A:I,6,FALSE) -> POR | R17: =VLOOKUP($B17,PickedPlayers!D:Q,11,FALSE) -> 0 | S17: =VLOOKUP($C17,Fixtures!A:I,7,FALSE) -> TBC | U17: =VLOOKUP($B17,PickedPlayers!D:Q,12,FALSE) -> 0 | V17: =VLOOKUP($C17,Fixtures!A:I,8,FALSE) -> TBC | X17: =VLOOKUP($B17,PickedPlayers!D:Q,13,FALSE) -> 0 | Y17: =VLOOKUP($C17,Fixtures!A:I,9,FALSE) -> TBC | AA17: =VLOOKUP($B17,PickedPlayers!D:Q,14,FALSE) -> 0
A18: FWD | B18: Matheus Cunha | C18: Brazil | D18: =VLOOKUP($C18,Fixtures!A:I,2,FALSE) -> MOR | E18: Sub 2 | F18: =VLOOKUP($B18,PickedPlayers!D:Q,7,FALSE) -> 0 | G18: =VLOOKUP($C18,Fixtures!A:I,3,FALSE) -> HAI | H18: Picked | I18: =VLOOKUP($B18,PickedPlayers!D:Q,8,FALSE) -> 0 | J18: =VLOOKUP($C18,Fixtures!A:I,4,FALSE) -> SCO | K18: Picked | L18: =VLOOKUP($B18,PickedPlayers!D:Q,9,FALSE) -> 0 | M18: =VLOOKUP($C18,Fixtures!A:I,5,FALSE) -> JAP | N18: Picked | O18: =VLOOKUP($B18,PickedPlayers!D:Q,10,FALSE) -> 0 | P18: =VLOOKUP($C18,Fixtures!A:I,6,FALSE) -> NOR | Q18: Picked | R18: =VLOOKUP($B18,PickedPlayers!D:Q,11,FALSE) -> 0 | S18: =VLOOKUP($C18,Fixtures!A:I,7,FALSE) -> TBC | U18: =VLOOKUP($B18,PickedPlayers!D:Q,12,FALSE) -> 0 | V18: =VLOOKUP($C18,Fixtures!A:I,8,FALSE) -> TBC | X18: =VLOOKUP($B18,PickedPlayers!D:Q,13,FALSE) -> 0 | Y18: =VLOOKUP($C18,Fixtures!A:I,9,FALSE) -> TBC | AA18: =VLOOKUP($B18,PickedPlayers!D:Q,14,FALSE) -> 0
A19: FWD | B19: M. Rashford | C19: England | D19: =VLOOKUP($C19,Fixtures!A:I,2,FALSE) -> CRO | E19: Sub 1 | F19: =VLOOKUP($B19,PickedPlayers!D:Q,7,FALSE) -> 0 | G19: =VLOOKUP($C19,Fixtures!A:I,3,FALSE) -> GHA | H19: Sub 1 | I19: =VLOOKUP($B19,PickedPlayers!D:Q,8,FALSE) -> 0 | J19: =VLOOKUP($C19,Fixtures!A:I,4,FALSE) -> PAN | K19: Captain | L19: =VLOOKUP($B19,PickedPlayers!D:Q,9,FALSE) -> 0 | M19: =VLOOKUP($C19,Fixtures!A:I,5,FALSE) -> CON | N19: Picked | O19: =VLOOKUP($B19,PickedPlayers!D:Q,10,FALSE) -> 0 | P19: =VLOOKUP($C19,Fixtures!A:I,6,FALSE) -> MEX | R19: =VLOOKUP($B19,PickedPlayers!D:Q,11,FALSE) -> 0 | S19: =VLOOKUP($C19,Fixtures!A:I,7,FALSE) -> TBC | U19: =VLOOKUP($B19,PickedPlayers!D:Q,12,FALSE) -> 0 | V19: =VLOOKUP($C19,Fixtures!A:I,8,FALSE) -> TBC | X19: =VLOOKUP($B19,PickedPlayers!D:Q,13,FALSE) -> 0 | Y19: =VLOOKUP($C19,Fixtures!A:I,9,FALSE) -> TBC | AA19: =VLOOKUP($B19,PickedPlayers!D:Q,14,FALSE) -> 0

Sheet Ian
A1: 1 Captain 1 Sub | D1: Group (1) | G1: Group (2) | J1: Group (3) | M1: Last 32 | P1: Last 16 | S1: Quarter Final | V1: Semi Final | Y1: 3rd Place / Final
A2: Position | B2: Player | C2: Nationality | D2: Opposition | E2: Selection | F2: Points | G2: Opposition | H2: Selection | I2: Points | J2: Opposition | K2: Selection | L2: Points | M2: Opposition | N2: Selection | O2: Points | P2: Opposition | Q2: Selection | R2: Points | S2: Opposition | T2: Selection | U2: Points | V2: Opposition | W2: Selection | X2: Points | Y2: Opposition | Z2: Selection | AA2: Points
A3: GK | B3: Unai Simón | C3: Spain | D3: =VLOOKUP($C3,Fixtures!A:I,2,FALSE) -> CAP | E3: Picked | F3: =VLOOKUP($B3,PickedPlayers!D:Q,7,FALSE) -> 0 | G3: =VLOOKUP($C3,Fixtures!A:I,3,FALSE) -> SAU | H3: Picked | I3: =VLOOKUP($B3,PickedPlayers!D:Q,8,FALSE) -> 0 | J3: =VLOOKUP($C3,Fixtures!A:I,4,FALSE) -> URU | K3: Picked | L3: =VLOOKUP($B3,PickedPlayers!D:Q,9,FALSE) -> 0 | M3: =VLOOKUP($C3,Fixtures!A:I,5,FALSE) -> AUS | N3: Picked | O3: =VLOOKUP($B3,PickedPlayers!D:Q,10,FALSE) -> 0 | P3: =VLOOKUP($C3,Fixtures!A:I,6,FALSE) -> POR | Q3: Picked | R3: =VLOOKUP($B3,PickedPlayers!D:Q,11,FALSE) -> 0 | S3: =VLOOKUP($C3,Fixtures!A:I,7,FALSE) -> TBC | U3: =VLOOKUP($B3,PickedPlayers!D:Q,12,FALSE) -> 0 | V3: =VLOOKUP($C3,Fixtures!A:I,8,FALSE) -> TBC | X3: =VLOOKUP($B3,PickedPlayers!D:Q,13,FALSE) -> 0 | Y3: =VLOOKUP($C3,Fixtures!A:I,9,FALSE) -> TBC | AA3: =VLOOKUP($B3,PickedPlayers!D:Q,14,FALSE) -> 0
